<?xml version="1.0"?>
<robot name="webcap_project">

  <link name="w"/>

  <joint name="world_to_servo1" type="fixed">
    <parent link="w"/>
    <child link="servo1"/>
    <origin xyz="0 0 0" rpy="0 0 0"/>
  </joint>

 <link name="servo1">
    <visual>
      <geometry>
        <cylinder length="0.2" radius="0.2"/>
      </geometry>
      <origin rpy="0 0 0" xyz="0 0 0.1"/>
    </visual>
  </link>

  <joint name="servo1_to_servo2" type="continuous">
    <parent link="servo1"/>
    <child link="servo2"/>
    <origin xyz="0 0 0.2"/>
    <axis xyz="0 0 1"/>
  </joint>

  <link name="servo2">
    <visual>
      <geometry>
         <sphere radius="0.2"/>
      </geometry>
      <origin rpy="0 0 0" xyz="0 0 0"/>
      <material name="blue">
        <color rgba="0 0 .8 1"/>
      </material>
    </visual>
  </link>

  <joint name="servo2_to_webcam" type="revolute">
    <limit effort="10.0" lower="-0.9" upper="0.6" velocity="0.5"/>
    <parent link="servo2"/>
    <child link="webcam"/>
    <origin xyz="0.15 0 0.15" rpy="0 1 0"/>
    <axis xyz="0 1 0"/>
  </joint>

  <link name="webcam">
    <visual>
      <geometry>
         <cylinder length="0.05" radius="0.05"/>
      </geometry>
      <origin rpy="0 0 0" xyz="0 0 0"/>
      <material name="white">
        <color rgba="1 1 1 1"/>
      </material>
    </visual>
  </link>
</robot>
