<?xml version="1.0"?>
<robot name="webcam_project">

  <link name="w"/>

  <joint name="world_to_servo1" type="fixed">
    <parent link="w"/>
    <child link="servo1"/>
    <origin xyz="0 0 0" rpy="0 0 0"/>
  </joint>

 <link name="servo1">
    <visual>
      <origin rpy="0 0 0" xyz="0.31 -0.325 0.05"/>
      <geometry>
        <mesh filename="package://webcam_description/meshes/Piece3.stl" scale="0.01 0.01 0.01"/>
      </geometry>
    </visual>
    <collision>
      <origin rpy="0 0 0" xyz="0 0 0"/>
      <geometry>
        <mesh filename="package://webcam_description/meshes/piece3_collision.stl"/>
      </geometry>
    </collision>
    <inertial>
      <origin rpy="0 0 0" xyz="-25.944387e-3 32.152683e-3 26.174015e-3"/>
      <mass value="95934.789062e-15"/>
      <inertia ixx="68891312e-6"
               ixy="121976.304688e-6"
               ixz="-2242330.5e-6"
               iyy="132973792e-6"
               iyz="-5062996e-6"
               izz="102348056e-6"/>
    </inertial>
 </link>

  <joint name="servo1_to_servo2" type="continuous">
    <parent link="servo1"/>
    <child link="servo2"/>
    <origin xyz="0 0 0.75"/>
    <axis xyz="0 0 1"/>
  </joint>

  <link name="servo2">   
    <visual>
      <origin rpy="0 0 0" xyz="0.31 -0.3 -0.7"/>
      <geometry>
        <mesh filename="package://webcam_description/meshes/Piece1.stl" scale="0.01 0.01 0.01"/>
      </geometry>
    </visual>
    <collision>
      <origin rpy="0 0 0" xyz="0 0 0"/>
      <geometry>
        <mesh filename="package://webcam_description/meshes/piece1_collision.stl"/>
      </geometry>
    </collision>
    <inertial>
      <origin rpy="0 0 0" xyz="-25.944387e-3 32.152683e-3 26.174015e-3"/>
      <mass value="95934.789062e-15"/>
      <inertia ixx="68891312e-6"
               ixy="121976.304688e-6"
               ixz="-2242330.5e-6"
               iyy="132973792e-6"
               iyz="-5062996e-6"
               izz="102348056e-6"/>
    </inertial>
  </link>

<joint name="servo2_to_webcam" type="revolute">
    <limit effort="10.0" lower="-0.9" upper="0.6" velocity="0.5"/>
    <parent link="servo2"/>
    <child link="webcam"/>
    <origin xyz="0.53 0 0.56" rpy="0 0 0"/>
    <axis xyz="1 0 0"/>
  </joint>

  <link name="webcam">    
    <visual>
      <origin rpy="0 0 0" xyz="-0.222 -0.25 -1.2"/>
      <geometry>
        <mesh filename="package://webcam_description/meshes/Piece2.stl" scale="0.01 0.01 0.01"/>
      </geometry>
    </visual>
    <collision>
      <origin rpy="0 0 0" xyz="0 0 0"/>
      <geometry>
        <mesh filename="package://webcam_description/meshes/piece2_collision.stl"/>
      </geometry>
    </collision>
    <inertial>
      <origin rpy="0 0 0" xyz="-25.944387e-3 32.152683e-3 26.174015e-3"/>
      <mass value="95934.789062e-15"/>
      <inertia ixx="68891312e-6"
               ixy="121976.304688e-6"
               ixz="-2242330.5e-6"
               iyy="132973792e-6"
               iyz="-5062996e-6"
               izz="102348056e-6"/>
    </inertial>
  </link>
</robot>
