<?xml version="1.0"?>
<robot name="webcam_project">

  <link name="w"/>

  <joint name="world_to_servo1" type="fixed">
    <parent link="w"/>
    <child link="servo1"/>
    <origin xyz="0 0 0" rpy="0 0 0"/>
  </joint>

 <link name="servo1">
    <visual>
      <origin rpy="0 0 0" xyz="0.31 -0.325 0.05"/>
      <geometry>
        <mesh filename="package://webcam_description/meshes/Piece3.stl" scale="0.01 0.01 0.01"/>
      </geometry>
	<material name="blue">
            <color rgba="0 0 1 1"/>
       </material>
    </visual>
    <collision>
      <origin rpy="0 0 0" xyz="0.31 -0.325 0.05"/>
      <geometry>
        <mesh filename="package://webcam_description/meshes/piece3_collision.stl" scale="0.01 0.01 0.01"/>
      </geometry>
    </collision>
    <inertial>
      <origin rpy="0 0 0" xyz="-25.944387e-3 32.152683e-3 26.174015e-3"/>
      <mass value="95934.789062e-15"/>
      <inertia ixx="68891312e-6"
               ixy="121976.304688e-6"
               ixz="-2242330.5e-6"
               iyy="132973792e-6"
               iyz="-5062996e-6"
               izz="102348056e-6"/>
    </inertial>
 </link>

  <joint name="servo1_to_servo2" type="continuous">
    <parent link="servo1"/>
    <child link="servo2"/>
    <origin xyz="0 0 0.75"/>
    <axis xyz="0 0 1"/>
  </joint>

  <link name="servo2">   
    <visual>
      <origin rpy="0 0 0" xyz="0.31 -0.3 -0.7"/>
      <geometry>
        <mesh filename="package://webcam_description/meshes/Piece1.stl" scale="0.01 0.01 0.01"/>
      </geometry>
	<material name="white">
            <color rgba="1 1 1 1"/>
       </material>
    </visual>
    <collision>
      <origin rpy="0 0 0" xyz="0.31 -0.3 -0.7"/>
      <geometry>
        <mesh filename="package://webcam_description/meshes/piece1_collision.stl" scale="0.01 0.01 0.01"/>
      </geometry>
    </collision>
    <inertial>
      <origin rpy="0 0 0" xyz="-31.285517e-3 45.131599e-3 109.967560e-3"/>
      <mass value="40842.414062e-15"/>
      <inertia ixx="36224836e-6"
               ixy="28357.201172e-6"
               ixz="196282.78e-6"
               iyy="79008008e-6"
               iyz="-3195690.5e-6"
               izz="65240460e-6"/>
    </inertial>
  </link>

<joint name="servo2_to_webcam_support" type="revolute">
    <limit effort="10.0" lower="-0.9" upper="0.2" velocity="0.5"/>
    <parent link="servo2"/>
    <child link="webcam_support"/>
    <origin xyz="0.53 0 0.54" rpy="0 0 0"/>
    <axis xyz="1 0 0"/>
  </joint>

  <link name="webcam_support">    
    <visual>
      <origin rpy="0 0 0" xyz="-0.222 -0.25 -1.27"/>
      <geometry>
        <mesh filename="package://webcam_description/meshes/Piece2.stl" scale="0.01 0.01 0.01"/>
      </geometry>
    </visual>
  </link>

 <joint name="webcam_support_to_webcam" type="fixed">
    <parent link="webcam_support"/>
    <child link="webcam"/>
    <origin xyz="-0.7 -0.3 -0.005" rpy="0 0 -1.575"/>
  </joint>

<link name="webcam">    
    <visual>
      <origin rpy="0 0 1.575" xyz="-0.042 0.45 -1.27"/>
      <geometry>
        <mesh filename="package://webcam_description/meshes/webcam.stl" scale="0.01 0.01 0.01"/>
      </geometry>
		<material name="green">
            <color rgba="0 1 0 1"/>
       </material>
    </visual>
  </link>

</robot>
